Workbook

Sheet Basic Stats
A1: Basic Cleerly Statistics from the Keto-CTA study in 2021-2024, hight of Covid Pandemic time frame.
A2: (this report is independent of the Lundquist institute and Dave Feldman)
A3: Chart | B3: Set | C3: N | D3: Mean X | E3: Mean Y | F3: SD X | G3: SD Y | H3: Annual Change (Slope) | I3: Y-Intercept | J3: Max X | K3: Max Y | L3: Min X | M3: Min Y | N3: p-value
A4: Tcpv0 vs. Tcpv1 | B4: Eta | C4: 17 | D4: 67.34706 | E4: 82.15882 | F4: 12.89579 | G4: 13.90437 | H4: 1.06137 | I4: 10.67851 | J4: 209.2 | K4: 215.4 | L4: 0 | M4: 0 | N4: 0.0001 | P4: Total regressions calculated 50240
A5: Cac0 vs. Cac1 | B5: Eta | C5: 17 | D5: 180.29412 | E5: 223.29412 | F5: 34.6864 | G5: 43.64879 | H5: 1.23466 | I5: 0.69135 | J5: 556 | K5: 768 | L5: 0 | M5: 0 | N5: 0.00025 | P5: Log mismatch regressions skipped: 14400
A6: Ncpv0 vs. Ncpv1 | B6: Eta | C6: 17 | D6: 183.34118 | E6: 249.84706 | F6: 29.35278 | G6: 38.26224 | H6: 1.27816 | I6: 15.50774 | J6: 450.6 | K6: 606.5 | L6: 0 | M6: 0 | N6: 0.00029 | P6: Inverse Ratio regressions included: 13050
A7: Pav0 vs. Pav1 | B7: Eta | C7: 17 | D7: 0.08276 | E7: 0.10588 | F7: 0.01102 | G7: 0.01326 | H7: 1.17972 | I7: 0.00824 | J7: 0.156 | K7: 0.2 | L7: 0 | M7: 0 | N7: 0.0003 | P7: Uninteresting regressions included in calculated (See Dust.IsInteresting flag): 15220 | AD7: λλ
A8: Tps0 vs. Tps1 | B8: Eta | C8: 17 | D8: 5.11765 | E8: 6.29412 | F8: 0.73889 | G8: 0.84208 | H8: 1.00463 | I8: 1.15278 | J8: 13 | K8: 14 | L8: 0 | M8: 0 | N8: 0.09987 | P8: Total interesting regressions: 8219
A9: Ncpv0 vs. Ncpv1 | B9: Gamma | C9: 48 | D9: 20.56042 | E9: 38.54583 | F9: 3.17748 | G9: 5.22728 | H9: 1.52236 | I9: 7.24558 | J9: 101.1 | K9: 156.6 | L9: 0 | M9: 0 | N9: 0.021 | P9: Interesting remaining regressions: 8219
A10: Pav0 vs. Pav1 | B10: Gamma | C10: 48 | D10: 0.007 | E10: 0.01365 | F10: 0.001 | G10: 0.00183 | H10: 1.55677 | I10: 0.00275 | J10: 0.025 | K10: 0.052 | L10: 0 | M10: 0 | N10: 0.11987
A11: Tcpv0 vs. Tcpv1 | B11: Gamma | C11: 48 | D11: 0.18333 | E11: 0.46458 | F11: 0.08856 | G11: 0.14874 | H11: 1.38755 | I11: 0.2102 | J11: 3.1 | K11: 4.5 | L11: 0 | M11: 0 | N11: 0.15787 | P11: Calculated Subset Regressions: | Y11: Calculated | Z11: Subset Regr | AA11: essions:
A12: Tps0 vs. Tps1 | B12: Gamma | C12: 48 | D12: 0.04167 | E12: 0.14583 | F12: 0.02946 | G12: 0.05203 | H12: 0.8913 | I12: 0.1087 | J12: 1 | K12: 1 | L12: 0 | M12: 0 | N12: 0.56996 | P12: Set | Q12: 0-0.2 | R12: 0.2-0.4 | S12: 0.4-0.6 | T12: 0.6-0.8 | U12: 0.8-1.0 | V12: NaN | W12: reconile | Y12: Set | Z12: 0-0.2 | AA12: 0.2-0.4 | AB12: 0.4-0.6 | AC12: 0.6-0.8 | AD12: 0.8-1.0 | AE12: NaN | AF12: reconcile
A13: Cac0 vs. Cac1 | B13: Gamma | C13: 48 | D13: 0 | E13: 0 | F13: 0 | G13: 0 | H13: NaN | I13: NaN | J13: 0 | K13: 0 | L13: 0 | M13: 0 | N13: 1 | P13: Omega | Q13: 209 | R13: 386 | S13: 865 | T13: 1945 | U13: 2875 | V13: 0 | W13: =SUM(Q13:V13) -> 6280 | Y13: Omega | Z13: 2964 | AA13: 3735 | AB13: 6600 | AC13: 11190 | AD13: 8649 | AE13: 0 | AF13: =SUM(Z13:AE13) -> 33138
A14: Tcpv0 vs. Tcpv1 | B14: Omega | C14: 100 | D14: 18.694 | E14: 22.701 | F14: 3.75625 | G14: 4.27434 | H14: 1.1276 | I14: 1.62159 | J14: 209.2 | K14: 215.4 | L14: 0 | M14: 0 | N14: 0 | P14: Alpha | Q14: 288 | R14: 483 | S14: 1098 | T14: 1920 | U14: 2491 | V14: 0 | W14: =SUM(Q14:V14) -> 6280 | Y14: Alpha | Z14: 3387 | AA14: 4218 | AB14: 7394 | AC14: 11691 | AD14: 8491 | AE14: 0 | AF14: =SUM(Z14:AE14) -> 35181
A15: Cac0 vs. Cac1 | B15: Omega | C15: 100 | D15: 50.28 | E15: 58.79 | F15: 10.13663 | G15: 12.09795 | H15: 1.1803 | I15: -0.55542 | J15: 556 | K15: 768 | L15: 0 | M15: 0 | N15: 0 | P15: Beta | Q15: 75 | R15: 187 | S15: 593 | T15: 1822 | U15: 3603 | V15: 0 | W15: =SUM(Q15:V15) -> 6280 | Y15: Beta | Z15: 2006 | AA15: 2754 | AB15: 5342 | AC15: 12665 | AD15: 10850 | AE15: 0 | AF15: =SUM(Z15:AE15) -> 33617
A16: Ncpv0 vs. Ncpv1 | B16: Omega | C16: 100 | D16: 75.879 | E16: 107.374 | F16: 8.87405 | G16: 11.3245 | H16: 1.25055 | I16: 12.4832 | J16: 450.6 | K16: 606.5 | L16: 0 | M16: 0 | N16: 0 | P16: Zeta | Q16: 166 | R16: 315 | S16: 657 | T16: 1811 | U16: 3331 | V16: 0 | W16: =SUM(Q16:V16) -> 6280 | Y16: Zeta | Z16: 1173 | AA16: 1796 | AB16: 3260 | AC16: 6504 | AD16: 5512 | AE16: 0 | AF16: =SUM(Z16:AE16) -> 18245
A17: Pav0 vs. Pav1 | B17: Omega | C17: 100 | D17: 0.03213 | E17: 0.04385 | F17: 0.0038 | G17: 0.00458 | H17: 1.17429 | I17: 0.00612 | J17: 0.156 | K17: 0.2 | L17: 0 | M17: 0 | N17: 4e-05 | P17: Gamma | Q17: 29 | R17: 72 | S17: 198 | T17: 613 | U17: 2154 | V17: 3214 | W17: =SUM(Q17:V17) -> 6280 | Y17: Gamma | Z17: 503 | AA17: 506 | AB17: 640 | AC17: 1402 | AD17: 1715 | AE17: 0 | AF17: =SUM(Z17:AE17) -> 4766
A18: Tps0 vs. Tps1 | B18: Omega | C18: 100 | D18: 1.66 | E18: 2.17 | F18: 0.26232 | G18: 0.3054 | H18: 1.09243 | I18: 0.35656 | J18: 13 | K18: 14 | L18: 0 | M18: 0 | N18: 0.00846 | P18: Theta | Q18: 59 | R18: 201 | S18: 705 | T18: 1859 | U18: 3456 | V18: 0 | W18: =SUM(Q18:V18) -> 6280 | Y18: Theta | Z18: 1371 | AA18: 1397 | AB18: 3069 | AC18: 8033 | AD18: 6814 | AE18: 0 | AF18: =SUM(Z18:AE18) -> 20684
A19: Cac0 vs. Cac1 | B19: Theta | C19: 23 | D19: 37.69565 | E19: 41.30435 | F19: 14.04133 | G19: 14.14629 | H19: 1.0065 | I19: 3.36367 | J19: 295 | K19: 300 | L19: 0 | M19: 0 | N19: 0 | P19: Eta | Q19: 110 | R19: 293 | S19: 521 | T19: 1965 | U19: 3391 | V19: 0 | W19: =SUM(Q19:V19) -> 6280 | Y19: Eta | Z19: 2115 | AA19: 3274 | AB19: 6364 | AC19: 12934 | AD19: 10001 | AE19: 0 | AF19: =SUM(Z19:AE19) -> 34688
A20: Tcpv0 vs. Tcpv1 | B20: Theta | C20: 23 | D20: 14.58696 | E20: 18.73478 | F20: 4.82196 | G20: 5.48658 | H20: 1.1091 | I20: 2.55643 | J20: 98.4 | K20: 109.1 | L20: 0 | M20: 0 | N20: 0.00043 | P20: BetaUZeta | Q20: 65 | R20: 149 | S20: 462 | T20: 1514 | U20: 4090 | V20: 0 | W20: =SUM(Q20:V20) -> 6280 | Y20: BetaUZeta | Z20: 2029 | AA20: 2771 | AB20: 4974 | AC20: 11638 | AD20: 11151 | AE20: 0 | AF20: =SUM(Z20:AE20) -> 32563
A21: Ncpv0 vs. Ncpv1 | B21: Theta | C21: 23 | D21: 103.11304 | E21: 141.19565 | F21: 16.12249 | G21: 18.28592 | H21: 1.07962 | I21: 29.87309 | J21: 290.2 | K21: 319.7 | L21: 0 | M21: 0 | N21: 0.00734 | P21: reconcile | Q21: =SUM(Q13:Q20) -> 1001 | R21: =SUM(R13:R20) -> 2086 | S21: =SUM(S13:S20) -> 5099 | T21: =SUM(T13:T20) -> 13449 | U21: =SUM(U13:U20) -> 25391 | V21: =SUM(V13:V20) -> 3214 | W21: =SUM(W13:W20) -> 50240 | Y21: reconcile | Z21: =SUM(Z12:Z19) -> 13519 | AA21: =SUM(AA12:AA19) -> 17680 | AB21: =SUM(AB12:AB19) -> 32669 | AC21: =SUM(AC12:AC19) -> 64419 | AD21: =SUM(AD12:AD19) -> 52032 | AE21: =SUM(AE12:AE19) -> 0 | AF21: =SUM(AF12:AF19) -> 180319
A22: Pav0 vs. Pav1 | B22: Theta | C22: 23 | D22: 0.03752 | E22: 0.05265 | F22: 0.00553 | G22: 0.007 | H22: 1.19393 | I22: 0.00785 | J22: 0.097 | K22: 0.121 | L22: 0 | M22: 0 | N22: 0.01291 | AG22: =SUM(AF13:AF19) -> 180319
A23: Tps0 vs. Tps1 | B23: Theta | C23: 23 | D23: 2.04348 | E23: 3.26087 | F23: 0.45217 | G23: 0.54248 | H23: 1.07865 | I23: 1.05668 | J23: 8 | K23: 10 | L23: 0 | M23: 0 | N23: 0.06312
A24: Tcpv0 vs. Tcpv1 | B24: Zeta | C24: 12 | D24: 31.68333 | E24: 35.01667 | F24: 14.47194 | G24: 15.46461 | H24: 1.06589 | I24: 1.24566 | J24: 128.6 | K24: 140.7 | L24: 0 | M24: 0 | N24: 0
A25: Cac0 vs. Cac1 | B25: Zeta | C25: 12 | D25: 91.33333 | E25: 94.41667 | F25: 37.59931 | G25: 40.82566 | H25: 1.07693 | I25: -3.94301 | J25: 360 | K25: 353 | L25: 0 | M25: 0 | N25: 3e-05
A26: Ncpv0 vs. Ncpv1 | B26: Zeta | C26: 12 | D26: 92.71667 | E26: 116.025 | F26: 18.06156 | G26: 22.31757 | H26: 1.20416 | I26: 4.37942 | J26: 193.3 | K26: 245 | L26: 0 | M26: 0 | N26: 0.00266
A27: Tps0 vs. Tps1 | B27: Zeta | C27: 12 | D27: 2.5 | E27: 2.33333 | F27: 0.8767 | G27: 0.76421 | H27: 0.82796 | I27: 0.26344 | J27: 8 | K27: 7 | L27: 0 | M27: 0 | N27: 0.01972
A28: Pav0 vs. Pav1 | B28: Zeta | C28: 12 | D28: 0.05058 | E28: 0.05992 | F28: 0.01106 | G28: 0.01121 | H28: 0.94322 | I28: 0.01221 | J28: 0.113 | K28: 0.121 | L28: 0 | M28: 0 | N28: 0.04286
A30: 📚 A Quick Regression Refresher (For the Non-Statisticians)
A31: Bear with me while I briefly over-explain this for those unfamiliar with regression…
A32: Linear regression is one of the most common statistical tools used to see how two sets of numbers relate to one another. It’s basically a smart average — a line of best fit — that helps reveal how one variable tends to increase or decrease in relation to another.
A33: Although the method of least squares was developed in the early 1800s by Gauss and Legendre, the term "regression" as we now use it in statistics was popularized in 1886 by Sir Francis Galton in his paper, “Regression Toward Mediocrity in Hereditary Stature.”
A34: In modern terms, a bivariate regression (two variables) compares:
A35: An independent variable (X) — the “regressor”
A36: A dependent variable (Y) — the one that changes in response
A38: You measure:
A39: Their means, standard deviations, and range (min/max)
A40: How much Y seems to "follow" X — that’s the slope
A41: How tightly the points hug the line — that’s the R² value
A42: And whether the correlation is statistically significant — via the p-value
...

Sheet Sheet4
A1: - | B1: - | C1: TdCac/DCac vs. GeoMeanTps/DCac - BetaUZeta | N1: - | O1: - | P1: Ln(MinNcpv/DNcpv) vs. TdNcpv - Gamma | Z1: - | AA1: - | AB1: TdCac vs. TdNcpv - BetaUZeta
A2: - | B2: - | C2: MeanX: 0.4149 moeX: 0.0351 StdDevX: 0.1142 Slope: 10.2520 StdErr: 6.3466 p-value: 0.113903 N=43 | N2: - | O2: - | P2: MeanX: 1.7697 moeX: 0.1083 StdDevX: 0.3520 Slope: 0.1454 StdErr: 0.0577 p-value: 0.015693 N=43 | Z2: - | AA2: - | AB2: MeanX: 3.5297 moeX: 0.1790 StdDevX: 0.5369 Slope: -0.6646 StdErr: 4.4930 p-value: 0.883257 N=37
A3: Id | B3: GeoMeanTps/DCac | C3: TdCac/DCac | N3: Id | O3: TdNcpv | P3: Ln(MinNcpv/DNcpv) | Z3: Id | AA3: TdNcpv | AB3: TdCac
A4: 81 | B4: 3.8729833 | C4: 55.79763 | N4: 45 | O4: 13.513407 | P4: 2.2024542 | Z4: 76 | AA4: 0.93356645 | AB4: 1.6509249
A5: 87 | B5: 2.4494897 | C5: 17.674687 | N5: 6 | O5: 5.4883739 | P5: 1.0371029 | Z5: 78 | AA5: 0.96976666 | AB5: 3.8452245
A6: 92 | B6: 1.4696938 | C6: 8.2482573 | N6: 27 | O6: 7.0702155 | P6: 0.86230321 | Z6: 64 | AA6: 1.0266371 | AB6: 11.260086
A7: 77 | B7: -0.42857143 | C7: 5.0428374 | N7: 44 | O7: 4.7048941 | P7: 0.71476791 | Z7: 87 | AA7: 1.1859528 | AB7: 35.349374
A8: 91 | B8: 1.2 | C8: 3.3682198 | N8: 36 | O8: 2.9902604 | P8: 0.47687048 | Z8: 97 | AA8: 1.5214246 | AB8: 4.9925449
A9: 64 | B9: 0.35355339 | C9: 2.8150215 | N9: 24 | O9: 1.2555454 | P9: 0.45028106 | Z9: 96 | AA9: 1.6475078 | AB9: 2.1458241
A10: 90 | B10: 0.45643546 | C10: 1.8963811 | N10: 42 | O10: 0.58268028 | P10: 0.43071988 | Z10: 81 | AA10: 1.6703212 | AB10: 55.79763
A11: 63 | B11: -0.23570226 | C11: 1.2506266 | N11: 21 | O11: 1.6216093 | P11: 0.35585775 | Z11: 82 | AA11: 1.770968 | AB11: 5.2423129
A12: 57 | B12: 0.5 | C12: 0.85475565 | N12: 31 | O12: 0.69086587 | P12: 0.33929845 | Z12: 85 | AA12: 1.8269386 | AB12: 5.3028537
A13: 97 | B13: 1.2777531 | C13: 0.7132207 | N13: 22 | O13: 0.5 | P13: 0.3384484 | Z13: 99 | AA13: 1.8904726 | AB13: 2.0510717
A14: 71 | B14: 1.2247449 | C14: 0.67845772 | N14: 40 | O14: 1.7780309 | P14: 0.33589402 | Z14: 94 | AA14: 2.0565491 | AB14: 3.6975155
A15: 61 | B15: 0.25 | C15: 0.47124046 | N15: 18 | O15: 1.0689931 | P15: 0.32378595 | Z15: 57 | AA15: 2.1462626 | AB15: 1.7095113
... A40: 96 | B40: 0.037735849 | C40: 0.010121812 | N40: 43 | O40: 0.8866646 | P40: 0.096290164 | Z40: 72 | AA40: 18.969584 | AB40: 1.9900484
A41: 2 | B41: 0 | C41: 0 | N41: 25 | O41: 0.54839524 | P41: 0.093014081 | Z41: Regression Set Mean X moe X Mean Y moe Y Slope StdErr xStdDev p-value
A42: 55 | B42: 0 | C42: 0 | N42: 15 | O42: 0.70432789 | P42: 0.091931758 | Z42: TdCac vs. TdNcpv Eta-17 2.950 0.262 4.493 0.641 0.0059 2.6042 0.5099 0.998224505
A43: 56 | B43: 0 | C43: 0 | N43: 23 | O43: 0.59516116 | P43: 0.087304724 | Z43: TdCac vs. TdNcpv Omega-37 3.530 0.179 6.016 0.791 -0.6646 4.4930 0.5369 0.883257022
A44: 59 | B44: 0 | C44: 0 | N44: 29 | O44: 1.5840299 | P44: 0.087252582 | Z44: TdCac vs. TdNcpv BetaUZeta-37 3.530 0.179 6.016 0.791 -0.6646 4.4930 0.5369 0.883257022
A45: 69 | B45: 0 | C45: 0 | N45: 58 | O45: 1.2386126 | P45: 0.077183499 | Z45: TdCac vs. TdNcpv Alpha-32 3.628 0.224 8.011 0.840 -0.7046 3.8103 0.6202 0.854535546
A46: 89 | B46: 0 | C46: 0 | N46: 48 | O46: 0.50836634 | P46: 0.058390303 | Z46: TdCac vs. TdNcpv Beta-32 3.628 0.224 8.011 0.840 -0.7046 3.8103 0.6202 0.854535546
A47: Regression Set Mean X moe X Mean Y moe Y Slope StdErr xStdDev p-value | N47: Regression Set Mean X moe X Mean Y moe Y Slope StdErr xStdDev p-value | Z47: TdCac vs. TdNcpv Theta-15 4.397 0.669 11.998 2.614 -1.2130 3.9874 1.2087 0.765790001
A48: TdCac/DCac vs. GeoMeanTps/DCac Gamma-48 0.000 0.000 0.000 0.000 NaN NaN 0.0000 1.00000000 | N48: Ln(MinNcpv/DNcpv) vs. TdNcpv Zeta-12 3.916 1.095 0.313 0.052 0.0243 0.0448 1.7242 0.599491481 | Z48: TdCac vs. TdNcpv Zeta-5 2.901 0.400 -6.755 10.486 -20.6757 20.8499 0.3219 0.394472157
A49: TdCac/DCac vs. GeoMeanTps/DCac Eta-17 0.193 0.018 0.231 0.057 1.9966 2.6092 0.0350 0.45602540 | N49: Ln(MinNcpv/DNcpv) vs. TdNcpv Theta-23 3.347 0.362 0.195 0.015 0.0226 0.0374 0.8374 0.552276939
A50: TdCac/DCac vs. GeoMeanTps/DCac Zeta-9 -0.022 0.063 0.760 0.450 -4.9929 5.8138 0.0819 0.41888178 | N50: Ln(MinNcpv/DNcpv) vs. TdNcpv BetaUZeta-52 3.349 0.152 0.203 0.008 0.0269 0.0426 0.5449 0.531048114
A51: TdCac/DCac vs. GeoMeanTps/DCac BetaUZeta-43 0.415 0.035 2.390 0.421 10.2520 6.3466 0.1142 0.11390263 | N51: Ln(MinNcpv/DNcpv) vs. TdNcpv Omega-95 2.634 0.070 0.255 0.006 0.0460 0.0718 0.3446 0.523155816
A52: TdCac/DCac vs. GeoMeanTps/DCac Omega-91 0.196 0.012 1.129 0.136 9.6004 6.0107 0.0576 0.11375973 | N52: Ln(MinNcpv/DNcpv) vs. TdNcpv Beta-40 3.178 0.166 0.171 0.008 0.0271 0.0395 0.5176 0.497210111
A53: TdCac/DCac vs. GeoMeanTps/DCac Alpha-82 0.220 0.014 1.170 0.158 9.9855 5.6666 0.0630 0.08185837 | N53: Ln(MinNcpv/DNcpv) vs. TdNcpv Alpha-83 2.449 0.069 0.247 0.007 0.0578 0.0825 0.3150 0.485971694
A54: TdCac/DCac vs. GeoMeanTps/DCac Theta-17 0.868 0.129 5.412 1.765 12.3003 6.2732 0.2517 0.06874695 | N54: Ln(MinNcpv/DNcpv) vs. TdNcpv Eta-17 2.950 0.262 0.138 0.017 0.0473 0.0444 0.5099 0.304174491
A55: TdCac/DCac vs. GeoMeanTps/DCac Beta-34 0.531 0.048 2.822 0.603 11.2669 5.8588 0.1369 0.06341021 | N55: Ln(MinNcpv/DNcpv) vs. TdNcpv Gamma-43 1.770 0.108 0.317 0.017 0.1454 0.0577 0.3520 0.015692733

Sheet Keto-CTA with change &Ln-Values
A1: Index | B1: Set | C1: Tps0 | D1: Tps1 | E1: Cac0 | F1: Cac1 | G1: Ncpv0 | H1: Ncpv1 | I1: Tcpv0 | J1: Tcpv1 | K1: Pav0 | L1: Pav1 | M1: LnTps0 | N1: LnTps1 | O1: LnCac0 | P1: LnCac1 | Q1: LnNcpv0 | R1: LnNcpv1 | S1: LnTcpv0 | T1: LnTcpv1 | U1: LnPav0 | V1: LnPav1 | W1: DTps | X1: DCac | Y1: DNcpv | Z1: DTcpv | AA1: DPav | AB1: LnDTps | AC1: LnDNcpv | AD1: LnDCac | AE1: LnDTcpv | AF1: LnDPav | AG1: Is Zeta | AH1: Column1
A2: 51 | B2: Zeta | C2: 0 | D2: 1 | E2: 6 | F2: 0 | G2: 19.6 | H2: 42 | I2: 1.5 | J2: 10.2 | K2: 0.01 | L2: 0.027 | M2: 0 | N2: 0.69314718 | O2: 1.9459101 | P2: 0 | Q2: 3.0252911 | R2: 3.7612001 | S2: 0.01 | T2: 0.91629073 | U2: 2.4159138 | V2: 0.0099503309 | W2: 0.026641931 | X2: -6 | Y2: 22.4 | Z2: 8.7 | AA2: 0.017 | AB2: 0.69314718 | AC2: 3.152736 | AD2: 1.9459101 | AE2: 2.2721259 | AF2: 0.016857117 | AG2: =AND("Zeta" ='Keto-CTA with change &Ln-Values'!$B52) -> FALSE | AH2: =ABS(X2) > 0 -> TRUE
A3: 1 | B3: Gamma | C3: 0 | D3: 0 | E3: 0 | F3: 0 | G3: 9.3 | H3: 18.8 | I3: 0 | J3: 0 | K3: 0.004 | L3: 0.007 | M3: 0 | N3: 0 | O3: 0 | P3: 0 | Q3: 2.3321439 | R3: 2.9856819 | S3: 0.004 | T3: 0 | U3: 0 | V3: 0.0039920213 | W3: 0.0069756137 | X3: 0 | Y3: 9.5 | Z3: 0 | AA3: 0.003 | AB3: 0 | AC3: 2.3513753 | AD3: 0 | AE3: 0 | AF3: 0.002995509 | AG3: =AND("Zeta" ='Keto-CTA with change &Ln-Values'!$B2) -> TRUE | AH3: =ABS(X3) > 0 -> FALSE
A4: 2 | B4: Zeta | C4: 0 | D4: 0 | E4: 0 | F4: 0 | G4: 193.3 | H4: 212.2 | I4: 0.1 | J4: 0 | K4: 0.067 | L4: 0.098 | M4: 0 | N4: 0 | O4: 0 | P4: 0 | Q4: 5.2694034 | R4: 5.3622307 | S4: 0.067 | T4: 0.09531018 | U4: 0 | V4: 0.064850972 | W4: 0.093490343 | X4: 0 | Y4: 18.9 | Z4: -0.1 | AA4: 0.031 | AB4: 0 | AC4: 2.9907197 | AD4: 0 | AE4: 0.09531018 | AF4: 0.030529205 | AG4: =AND("Zeta" ='Keto-CTA with change &Ln-Values'!$B3) -> FALSE | AH4: =ABS(X4) > 0 -> FALSE
A5: 3 | B5: Gamma | C5: 0 | D5: 0 | E5: 0 | F5: 0 | G5: 6.5 | H5: 23.2 | I5: 0 | J5: 0.2 | K5: 0.003 | L5: 0.008 | M5: 0 | N5: 0 | O5: 0 | P5: 0 | Q5: 2.014903 | R5: 3.1863526 | S5: 0.003 | T5: 0 | U5: 0.18232156 | V5: 0.002995509 | W5: 0.0079681696 | X5: 0 | Y5: 16.7 | Z5: 0.2 | AA5: 0.005 | AB5: 0 | AC5: 2.8735646 | AD5: 0 | AE5: 0.18232156 | AF5: 0.0049875415 | AG5: =AND("Zeta" ='Keto-CTA with change &Ln-Values'!$B4) -> TRUE | AH5: =ABS(X5) > 0 -> FALSE
A6: 4 | B6: Gamma | C6: 0 | D6: 0 | E6: 0 | F6: 0 | G6: 1.8 | H6: 9.1 | I6: 0 | J6: 0.9 | K6: 0.001 | L6: 0.005 | M6: 0 | N6: 0 | O6: 0 | P6: 0 | Q6: 1.0296194 | R6: 2.3125354 | S6: 0.001 | T6: 0 | U6: 0.64185389 | V6: 0.00099950033 | W6: 0.0049875415 | X6: 0 | Y6: 7.3 | Z6: 0.9 | AA6: 0.004 | AB6: 0 | AC6: 2.1162555 | AD6: 0 | AE6: 0.64185389 | AF6: 0.0039920213 | AG6: =AND("Zeta" ='Keto-CTA with change &Ln-Values'!$B5) -> FALSE | AH6: =ABS(X6) > 0 -> FALSE
A7: 5 | B7: Gamma | C7: 0 | D7: 0 | E7: 0 | F7: 0 | G7: 15.6 | H7: 24.8 | I7: 0 | J7: 0.6 | K7: 0.007 | L7: 0.01 | M7: 0 | N7: 0 | O7: 0 | P7: 0 | Q7: 2.8094027 | R7: 3.2503745 | S7: 0.007 | T7: 0 | U7: 0.47000363 | V7: 0.0069756137 | W7: 0.0099503309 | X7: 0 | Y7: 9.2 | Z7: 0.6 | AA7: 0.003 | AB7: 0 | AC7: 2.3223877 | AD7: 0 | AE7: 0.47000363 | AF7: 0.002995509 | AG7: =AND("Zeta" ='Keto-CTA with change &Ln-Values'!$B6) -> FALSE | AH7: =ABS(X7) > 0 -> FALSE
A8: 6 | B8: Gamma | C8: 0 | D8: 0 | E8: 0 | F8: 0 | G8: 10.4 | H8: 11.8 | I8: 0 | J8: 0.5 | K8: 0.005 | L8: 0.006 | M8: 0 | N8: 0 | O8: 0 | P8: 0 | Q8: 2.4336134 | R8: 2.5494452 | S8: 0.005 | T8: 0 | U8: 0.40546511 | V8: 0.0049875415 | W8: 0.0059820717 | X8: 0 | Y8: 1.4 | Z8: 0.5 | AA8: 0.001 | AB8: 0 | AC8: 0.87546874 | AD8: 0 | AE8: 0.40546511 | AF8: 0.00099950033 | AG8: =AND("Zeta" ='Keto-CTA with change &Ln-Values'!$B7) -> FALSE | AH8: =ABS(X8) > 0 -> FALSE
A9: 7 | B9: Gamma | C9: 0 | D9: 0 | E9: 0 | F9: 0 | G9: 48.4 | H9: 80.4 | I9: 0.8 | J9: 3.8 | K9: 0.025 | L9: 0.03 | M9: 0 | N9: 0 | O9: 0 | P9: 0 | Q9: 3.8999504 | R9: 4.3993753 | S9: 0.025 | T9: 0.58778666 | U9: 1.5686159 | V9: 0.024692613 | W9: 0.029558802 | X9: 0 | Y9: 32 | Z9: 3 | AA9: 0.005 | AB9: 0 | AC9: 3.4965076 | AD9: 0 | AE9: 1.3862944 | AF9: 0.0049875415 | AG9: =AND("Zeta" ='Keto-CTA with change &Ln-Values'!$B8) -> FALSE | AH9: =ABS(X9) > 0 -> FALSE
A10: 8 | B10: Gamma | C10: 0 | D10: 0 | E10: 0 | F10: 0 | G10: 65.6 | H10: 82.5 | I10: 0 | J10: 0.1 | K10: 0.017 | L10: 0.021 | M10: 0 | N10: 0 | O10: 0 | P10: 0 | Q10: 4.1987046 | R10: 4.4248466 | S10: 0.017 | T10: 0 | U10: 0.09531018 | V10: 0.016857117 | W10: 0.020782539 | X10: 0 | Y10: 16.9 | Z10: 0.1 | AA10: 0.004 | AB10: 0 | AC10: 2.8848007 | AD10: 0 | AE10: 0.09531018 | AF10: 0.0039920213 | AG10: =AND("Zeta" ='Keto-CTA with change &Ln-Values'!$B9) -> FALSE | AH10: =ABS(X10) > 0 -> FALSE
A11: 9 | B11: Gamma | C11: 0 | D11: 0 | E11: 0 | F11: 0 | G11: 3.8 | H11: 13.1 | I11: 0 | J11: 0 | K11: 0.001 | L11: 0.004 | M11: 0 | N11: 0 | O11: 0 | P11: 0 | Q11: 1.5686159 | R11: 2.6461748 | S11: 0.001 | T11: 0 | U11: 0 | V11: 0.00099950033 | W11: 0.0039920213 | X11: 0 | Y11: 9.3 | Z11: 0 | AA11: 0.003 | AB11: 0 | AC11: 2.3321439 | AD11: 0 | AE11: 0 | AF11: 0.002995509 | AG11: =AND("Zeta" ='Keto-CTA with change &Ln-Values'!$B10) -> FALSE | AH11: =ABS(X11) > 0 -> FALSE
A12: 10 | B12: Gamma | C12: 0 | D12: 0 | E12: 0 | F12: 0 | G12: 42.8 | H12: 64.4 | I12: 0 | J12: 0 | K12: 0.012 | L12: 0.017 | M12: 0 | N12: 0 | O12: 0 | P12: 0 | Q12: 3.7796338 | R12: 4.1805223 | S12: 0.012 | T12: 0 | U12: 0 | V12: 0.011928571 | W12: 0.016857117 | X12: 0 | Y12: 21.6 | Z12: 0 | AA12: 0.005 | AB12: 0 | AC12: 3.1179499 | AD12: 0 | AE12: 0 | AF12: 0.0049875415 | AG12: =AND("Zeta" ='Keto-CTA with change &Ln-Values'!$B11) -> FALSE | AH12: =ABS(X12) > 0 -> FALSE
A13: 11 | B13: Gamma | C13: 0 | D13: 0 | E13: 0 | F13: 0 | G13: 21.7 | H13: 44.4 | I13: 2.8 | J13: 4.5 | K13: 0.012 | L13: 0.02 | M13: 0 | N13: 0 | O13: 0 | P13: 0 | Q13: 3.1223649 | R13: 3.8155121 | S13: 0.012 | T13: 1.3350011 | U13: 1.7047481 | V13: 0.011928571 | W13: 0.019802627 | X13: 0 | Y13: 22.7 | Z13: 1.7 | AA13: 0.008 | AB13: 0 | AC13: 3.165475 | AD13: 0 | AE13: 0.99325177 | AF13: 0.0079681696 | AG13: =AND("Zeta" ='Keto-CTA with change &Ln-Values'!$B12) -> FALSE | AH13: =ABS(X13) > 0 -> FALSE | AI13: Sort by isZeta decend, DCAC decend, DNCPV decend
A14: 12 | B14: Gamma | C14: 0 | D14: 0 | E14: 0 | F14: 0 | G14: 4.9 | H14: 16.7 | I14: 0 | J14: 0 | K14: 0.002 | L14: 0.006 | M14: 0 | N14: 0 | O14: 0 | P14: 0 | Q14: 1.7749524 | R14: 2.8735646 | S14: 0.002 | T14: 0 | U14: 0 | V14: 0.0019980027 | W14: 0.0059820717 | X14: 0 | Y14: 11.8 | Z14: 0 | AA14: 0.004 | AB14: 0 | AC14: 2.5494452 | AD14: 0 | AE14: 0 | AF14: 0.0039920213 | AG14: =AND("Zeta" ='Keto-CTA with change &Ln-Values'!$B13) -> FALSE | AH14: =ABS(X14) > 0 -> FALSE
A15: 13 | B15: Gamma | C15: 0 | D15: 0 | E15: 0 | F15: 0 | G15: 27.8 | H15: 39.3 | I15: 0 | J15: 0 | K15: 0.006 | L15: 0.008 | M15: 0 | N15: 0 | O15: 0 | P15: 0 | Q15: 3.3603754 | R15: 3.6963515 | S15: 0.006 | T15: 0 | U15: 0 | V15: 0.0059820717 | W15: 0.0079681696 | X15: 0 | Y15: 11.5 | Z15: 0 | AA15: 0.002 | AB15: 0 | AC15: 2.5257286 | AD15: 0 | AE15: 0 | AF15: 0.0019980027 | AG15: =AND("Zeta" ='Keto-CTA with change &Ln-Values'!$B14) -> FALSE | AH15: =ABS(X15) > 0 -> FALSE
A16: 14 | B16: Gamma | C16: 0 | D16: 0 | E16: 0 | F16: 0 | G16: 22.4 | H16: 55.9 | I16: 0 | J16: 0.1 | K16: 0.006 | L16: 0.016 | M16: 0 | N16: 0 | O16: 0 | P16: 0 | Q16: 3.152736 | R16: 4.0412953 | S16: 0.006 | T16: 0 | U16: 0.09531018 | V16: 0.0059820717 | W16: 0.015873349 | X16: 0 | Y16: 33.5 | Z16: 0.1 | AA16: 0.01 | AB16: 0 | AC16: 3.5409593 | AD16: 0 | AE16: 0.09531018 | AF16: 0.0099503309 | AG16: =AND("Zeta" ='Keto-CTA with change &Ln-Values'!$B15) -> FALSE | AH16: =ABS(X16) > 0 -> FALSE
A17: 15 | B17: Gamma | C17: 0 | D17: 0 | E17: 0 | F17: 0 | G17: 26.5 | H17: 70.9 | I17: 0.1 | J17: 0.3 | K17: 0.009 | L17: 0.024 | M17: 0 | N17: 0 | O17: 0 | P17: 0 | Q17: 3.314186 | R17: 4.2752763 | S17: 0.009 | T17: 0.09531018 | U17: 0.26236426 | V17: 0.0089597414 | W17: 0.023716527 | X17: 0 | Y17: 44.4 | Z17: 0.2 | AA17: 0.015 | AB17: 0 | AC17: 3.8155121 | AD17: 0 | AE17: 0.18232156 | AF17: 0.014888612 | AG17: =AND("Zeta" ='Keto-CTA with change &Ln-Values'!$B16) -> FALSE | AH17: =ABS(X17) > 0 -> FALSE
A18: 16 | B18: Gamma | C18: 0 | D18: 0 | E18: 0 | F18: 0 | G18: 0 | H18: 0 | I18: 0 | J18: 0 | K18: 0 | L18: 0 | M18: 0 | N18: 0 | O18: 0 | P18: 0 | Q18: 0 | R18: 0 | S18: 0 | T18: 0 | U18: 0 | V18: 0 | W18: 0 | X18: 0 | Y18: 0 | Z18: 0 | AA18: 0 | AB18: 0 | AC18: 0 | AD18: 0 | AE18: 0 | AF18: 0 | AG18: =AND("Zeta" ='Keto-CTA with change &Ln-Values'!$B17) -> FALSE | AH18: =ABS(X18) > 0 -> FALSE
A19: 18 | B19: Gamma | C19: 0 | D19: 0 | E19: 0 | F19: 0 | G19: 8 | H19: 15.3 | I19: 0 | J19: 0 | K19: 0.002 | L19: 0.004 | M19: 0 | N19: 0 | O19: 0 | P19: 0 | Q19: 2.1972246 | R19: 2.7911651 | S19: 0.002 | T19: 0 | U19: 0 | V19: 0.0019980027 | W19: 0.0039920213 | X19: 0 | Y19: 7.3 | Z19: 0 | AA19: 0.002 | AB19: 0 | AC19: 2.1162555 | AD19: 0 | AE19: 0 | AF19: 0.0019980027 | AG19: =AND("Zeta" ='Keto-CTA with change &Ln-Values'!$B19) -> FALSE | AH19: =ABS(X19) > 0 -> FALSE
A20: 19 | B20: Gamma | C20: 0 | D20: 0 | E20: 0 | F20: 0 | G20: 0 | H20: 13.6 | I20: 0 | J20: 2.5 | K20: 0 | L20: 0.012 | M20: 0 | N20: 0 | O20: 0 | P20: 0 | Q20: 0 | R20: 2.6810215 | S20: 0 | T20: 0 | U20: 1.252763 | V20: 0 | W20: 0.011928571 | X20: 0 | Y20: 13.6 | Z20: 2.5 | AA20: 0.012 | AB20: 0 | AC20: 2.6810215 | AD20: 0 | AE20: 1.252763 | AF20: 0.011928571 | AG20: =AND("Zeta" ='Keto-CTA with change &Ln-Values'!$B20) -> FALSE | AH20: =ABS(X20) > 0 -> FALSE
A21: 20 | B21: Gamma | C21: 0 | D21: 0 | E21: 0 | F21: 0 | G21: 45.7 | H21: 64 | I21: 0 | J21: 0 | K21: 0.017 | L21: 0.024 | M21: 0 | N21: 0 | O21: 0 | P21: 0 | Q21: 3.8437442 | R21: 4.1743873 | S21: 0.017 | T21: 0 | U21: 0 | V21: 0.016857117 | W21: 0.023716527 | X21: 0 | Y21: 18.3 | Z21: 0 | AA21: 0.007 | AB21: 0 | AC21: 2.9601051 | AD21: 0 | AE21: 0 | AF21: 0.0069756137 | AG21: =AND("Zeta" ='Keto-CTA with change &Ln-Values'!$B21) -> FALSE | AH21: =ABS(X21) > 0 -> FALSE
A22: 21 | B22: Gamma | C22: 0 | D22: 0 | E22: 0 | F22: 0 | G22: 13.5 | H22: 20.7 | I22: 0 | J22: 0 | K22: 0.005 | L22: 0.011 | M22: 0 | N22: 0 | O22: 0 | P22: 0 | Q22: 2.6741486 | R22: 3.0773123 | S22: 0.005 | T22: 0 | U22: 0 | V22: 0.0049875415 | W22: 0.01093994 | X22: 0 | Y22: 7.2 | Z22: 0 | AA22: 0.006 | AB22: 0 | AC22: 2.1041342 | AD22: 0 | AE22: 0 | AF22: 0.0059820717 | AG22: =AND("Zeta" ='Keto-CTA with change &Ln-Values'!$B22) -> FALSE | AH22: =ABS(X22) > 0 -> FALSE
A23: 22 | B23: Gamma | C23: 0 | D23: 0 | E23: 0 | F23: 0 | G23: 1.7 | H23: 6.8 | I23: 0 | J23: 0.2 | K23: 0.001 | L23: 0.003 | M23: 0 | N23: 0 | O23: 0 | P23: 0 | Q23: 0.99325177 | R23: 2.0541237 | S23: 0.001 | T23: 0 | U23: 0.18232156 | V23: 0.00099950033 | W23: 0.002995509 | X23: 0 | Y23: 5.1 | Z23: 0.2 | AA23: 0.002 | AB23: 0 | AC23: 1.8082888 | AD23: 0 | AE23: 0.18232156 | AF23: 0.0019980027 | AG23: =AND("Zeta" ='Keto-CTA with change &Ln-Values'!$B23) -> FALSE | AH23: =ABS(X23) > 0 -> FALSE
A24: 23 | B24: Gamma | C24: 0 | D24: 0 | E24: 0 | F24: 0 | G24: 21 | H24: 67.3 | I24: 0.3 | J24: 0.4 | K24: 0.005 | L24: 0.016 | M24: 0 | N24: 0 | O24: 0 | P24: 0 | Q24: 3.0910425 | R24: 4.2239098 | S24: 0.005 | T24: 0.26236426 | U24: 0.33647224 | V24: 0.0049875415 | W24: 0.015873349 | X24: 0 | Y24: 46.3 | Z24: 0.1 | AA24: 0.011 | AB24: 0 | AC24: 3.8565103 | AD24: 0 | AE24: 0.09531018 | AF24: 0.01093994 | AG24: =AND("Zeta" ='Keto-CTA with change &Ln-Values'!$B24) -> FALSE | AH24: =ABS(X24) > 0 -> FALSE
A25: 24 | B25: Gamma | C25: 0 | D25: 0 | E25: 0 | F25: 0 | G25: 5.7 | H25: 9.9 | I25: 0 | J25: 0 | K25: 0.001 | L25: 0.002 | M25: 0 | N25: 0 | O25: 0 | P25: 0 | Q25: 1.9021075 | R25: 2.3887628 | S25: 0.001 | T25: 0 | U25: 0 | V25: 0.00099950033 | W25: 0.0019980027 | X25: 0 | Y25: 4.2 | Z25: 0 | AA25: 0.001 | AB25: 0 | AC25: 1.6486586 | AD25: 0 | AE25: 0 | AF25: 0.00099950033 | AG25: =AND("Zeta" ='Keto-CTA with change &Ln-Values'!$B25) -> FALSE | AH25: =ABS(X25) > 0 -> FALSE
A26: 25 | B26: Gamma | C26: 0 | D26: 0 | E26: 0 | F26: 0 | G26: 16.5 | H26: 58.4 | I26: 0 | J26: 0 | K26: 0.005 | L26: 0.019 | M26: 0 | N26: 0 | O26: 0 | P26: 0 | Q26: 2.8622009 | R26: 4.0842942 | S26: 0.005 | T26: 0 | U26: 0 | V26: 0.0049875415 | W26: 0.018821754 | X26: 0 | Y26: 41.9 | Z26: 0 | AA26: 0.014 | AB26: 0 | AC26: 3.7588718 | AD26: 0 | AE26: 0 | AF26: 0.013902905 | AG26: =AND("Zeta" ='Keto-CTA with change &Ln-Values'!$B26) -> FALSE | AH26: =ABS(X26) > 0 -> FALSE
A27: 26 | B27: Gamma | C27: 0 | D27: 0 | E27: 0 | F27: 0 | G27: 0 | H27: 9.2 | I27: 0 | J27: 0 | K27: 0 | L27: 0.004 | M27: 0 | N27: 0 | O27: 0 | P27: 0 | Q27: 0 | R27: 2.3223877 | S27: 0 | T27: 0 | U27: 0 | V27: 0 | W27: 0.0039920213 | X27: 0 | Y27: 9.2 | Z27: 0 | AA27: 0.004 | AB27: 0 | AC27: 2.3223877 | AD27: 0 | AE27: 0 | AF27: 0.0039920213 | AG27: =AND("Zeta" ='Keto-CTA with change &Ln-Values'!$B27) -> FALSE | AH27: =ABS(X27) > 0 -> FALSE
A28: 27 | B28: Gamma | C28: 0 | D28: 0 | E28: 0 | F28: 0 | G28: 23.3 | H28: 25.7 | I28: 0.1 | J28: 0.1 | K28: 0.008 | L28: 0.008 | M28: 0 | N28: 0 | O28: 0 | P28: 0 | Q28: 3.1904764 | R28: 3.2846636 | S28: 0.008 | T28: 0.09531018 | U28: 0.09531018 | V28: 0.0079681696 | W28: 0.0079681696 | X28: 0 | Y28: 2.4 | Z28: 0 | AA28: 0 | AB28: 0 | AC28: 1.2237754 | AD28: 0 | AE28: 0 | AF28: 0 | AG28: =AND("Zeta" ='Keto-CTA with change &Ln-Values'!$B28) -> FALSE | AH28: =ABS(X28) > 0 -> FALSE
A29: 28 | B29: Gamma | C29: 0 | D29: 0 | E29: 0 | F29: 0 | G29: 5.3 | H29: 5.3 | I29: 0 | J29: 0.1 | K29: 0.002 | L29: 0.002 | M29: 0 | N29: 0 | O29: 0 | P29: 0 | Q29: 1.8405496 | R29: 1.8405496 | S29: 0.002 | T29: 0 | U29: 0.09531018 | V29: 0.0019980027 | W29: 0.0019980027 | X29: 0 | Y29: 0 | Z29: 0.1 | AA29: 0 | AB29: 0 | AC29: 0 | AD29: 0 | AE29: 0.09531018 | AF29: 0 | AG29: =AND("Zeta" ='Keto-CTA with change &Ln-Values'!$B29) -> FALSE | AH29: =ABS(X29) > 0 -> FALSE
A30: 29 | B30: Gamma | C30: 0 | D30: 0 | E30: 0 | F30: 0 | G30: 101.1 | H30: 156.6 | I30: 0 | J30: 0 | K30: 0.024 | L30: 0.038 | M30: 0 | N30: 0 | O30: 0 | P30: 0 | Q30: 4.6259527 | R30: 5.0600602 | S30: 0.024 | T30: 0 | U30: 0 | V30: 0.023716527 | W30: 0.037295785 | X30: 0 | Y30: 55.5 | Z30: 0 | AA30: 0.014 | AB30: 0 | AC30: 4.0342406 | AD30: 0 | AE30: 0 | AF30: 0.013902905 | AG30: =AND("Zeta" ='Keto-CTA with change &Ln-Values'!$B30) -> FALSE | AH30: =ABS(X30) > 0 -> FALSE
... A48: 47 | B48: Gamma | C48: 0 | D48: 1 | E48: 0 | F48: 0 | G48: 61.8 | H48: 98.3 | I48: 0 | J48: 0.1 | K48: 0.016 | L48: 0.024 | M48: 0 | N48: 0.69314718 | O48: 0 | P48: 0 | Q48: 4.1399551 | R48: 4.5981456 | S48: 0.016 | T48: 0 | U48: 0.09531018 | V48: 0.015873349 | W48: 0.023716527 | X48: 0 | Y48: 36.5 | Z48: 0.1 | AA48: 0.008 | AB48: 0.69314718 | AC48: 3.6243409 | AD48: 0 | AE48: 0.09531018 | AF48: 0.0079681696 | AG48: =AND("Zeta" ='Keto-CTA with change &Ln-Values'!$B48) -> FALSE | AH48: =ABS(X48) > 0 -> FALSE
A49: 55 | B49: Zeta | C49: 1 | D49: 0 | E49: 0 | F49: 0 | G49: 68.2 | H49: 71.4 | I49: 0 | J49: 0 | K49: 0.023 | L49: 0.031 | M49: 0.69314718 | N49: 0 | O49: 0 | P49: 0 | Q49: 4.2370009 | R49: 4.2822063 | S49: 0.023 | T49: 0 | U49: 0 | V49: 0.022739487 | W49: 0.03052920503482279-1 | X49: 0 | Y49: 3.2 | Z49: 0 | AA49: 0.008 | AB49: 0.69314718 | AC49: 1.4350845 | AD49: 0 | AE49: 0 | AF49: 0.0079681696 | AG49: =AND("Zeta" ='Keto-CTA with change &Ln-Values'!$B56) -> TRUE | AH49: =ABS(X49) > 0 -> FALSE
A50: 56 | B50: Zeta | C50: 1 | D50: 0 | E50: 0 | F50: 0 | G50: 15.5 | H50: 31 | I50: 0 | J50: 0 | K50: 0.006 | L50: 0.012 | M50: 0.69314718 | N50: 0 | O50: 0 | P50: 0 | Q50: 2.8033604 | R50: 3.4657359 | S50: 0.006 | T50: 0 | U50: 0 | V50: 0.0059820717 | W50: 0.011928570865273812-1 | X50: 0 | Y50: 15.5 | Z50: 0 | AA50: 0.006 | AB50: 0.69314718 | AC50: 2.8033604 | AD50: 0 | AE50: 0 | AF50: 0.0059820717 | AG50: =AND("Zeta" ='Keto-CTA with change &Ln-Values'!$B57) -> TRUE | AH50: =ABS(X50) > 0 -> FALSE
A51: 48 | B51: Gamma | C51: 0 | D51: 1 | E51: 0 | F51: 0 | G51: 26.6 | H51: 104 | I51: 0 | J51: 0.1 | K51: 0.011 | L51: 0.052 | M51: 0 | N51: 0.69314718 | O51: 0 | P51: 0 | Q51: 3.3178158 | R51: 4.6539604 | S51: 0.011 | T51: 0 | U51: 0.09531018 | V51: 0.01093994 | W51: 0.050693114 | X51: 0 | Y51: 77.4 | Z51: 0.1 | AA51: 0.041 | AB51: 0.69314718 | AC51: 4.3618239 | AD51: 0 | AE51: 0.09531018 | AF51: 0.04018179 | AG51: =AND("Zeta" ='Keto-CTA with change &Ln-Values'!$B49) -> TRUE | AH51: =ABS(X51) > 0 -> FALSE
A52: 17 | B52: Theta | C52: 0 | D52: 0 | E52: 0 | F52: 1 | G52: 6.3 | H52: 19.8 | I52: 1 | J52: 3.4 | K52: 0.003 | L52: 0.009 | M52: 0 | N52: 0 | O52: 0 | P52: 0.69314718 | Q52: 1.9878743 | R52: 3.034953 | S52: 0.003 | T52: 0.69314718 | U52: 1.4816045 | V52: 0.002995509 | W52: 0.0089597414 | X52: 1 | Y52: 13.5 | Z52: 2.4 | AA52: 0.006 | AB52: 0 | AC52: 2.6741486 | AD52: 0.69314718 | AE52: 1.2237754 | AF52: 0.0059820717 | AG52: =AND("Zeta" ='Keto-CTA with change &Ln-Values'!$B18) -> FALSE | AH52: =ABS(X52) > 0 -> TRUE
A53: 50 | B53: Theta | C53: 0 | D53: 1 | E53: 0 | F53: 1 | G53: 26.3 | H53: 60.7 | I53: 1.1 | J53: 2 | K53: 0.009 | L53: 0.021 | M53: 0 | N53: 0.69314718 | O53: 0 | P53: 0.69314718 | Q53: 3.3068867 | R53: 4.1222839 | S53: 0.009 | T53: 0.74193734 | U53: 1.0986123 | V53: 0.0089597414 | W53: 0.020782539 | X53: 1 | Y53: 34.4 | Z53: 0.9 | AA53: 0.012 | AB53: 0.69314718 | AC53: 3.5667118 | AD53: 0.69314718 | AE53: 0.64185389 | AF53: 0.011928571 | AG53: =AND("Zeta" ='Keto-CTA with change &Ln-Values'!$B51) -> FALSE | AH53: =ABS(X53) > 0 -> TRUE
A54: 57 | B54: Theta | C54: 1 | D54: 1 | E54: 4 | F54: 6 | G54: 94.7 | H54: 130.8 | I54: 2.8 | J54: 3.1 | K54: 0.031 | L54: 0.038 | M54: 0.69314718 | N54: 0.69314718 | O54: 1.6094379 | P54: 1.9459101 | Q54: 4.5612183 | R54: 4.8812856 | S54: 0.031 | T54: 1.3350011 | U54: 1.410987 | V54: 0.030529205 | W54: 0.037295785 | X54: 2 | Y54: 36.1 | Z54: 0.3 | AA54: 0.007 | AB54: 0 | AC54: 3.613617 | AD54: 1.0986123 | AE54: 0.26236426 | AF54: 0.0069756137 | AG54: =AND("Zeta" ='Keto-CTA with change &Ln-Values'!$B58) -> TRUE | AH54: =ABS(X54) > 0 -> TRUE
A55: 49 | B55: Theta | C55: 0 | D55: 1 | E55: 0 | F55: 2 | G55: 39.7 | H55: 57 | I55: 1.4 | J55: 4.4 | K55: 0.015 | L55: 0.023 | M55: 0 | N55: 0.69314718 | O55: 0 | P55: 1.0986123 | Q55: 3.7062281 | R55: 4.060443 | S55: 0.015 | T55: 0.87546874 | U55: 1.686399 | V55: 0.014888612 | W55: 0.022739487 | X55: 2 | Y55: 17.3 | Z55: 3 | AA55: 0.008 | AB55: 0.69314718 | AC55: 2.9069011 | AD55: 1.0986123 | AE55: 1.3862944 | AF55: 0.0079681696 | AG55: =AND("Zeta" ='Keto-CTA with change &Ln-Values'!$B50) -> TRUE | AH55: =ABS(X55) > 0 -> TRUE
A56: 66 | B56: Zeta | C56: 1 | D56: 2 | E56: 58 | F56: 39 | G56: 91.1 | H56: 119.7 | I56: 21.8 | J56: 22.9 | K56: 0.031 | L56: 0.04 | M56: 0.69314718 | N56: 1.0986123 | O56: 4.0775374 | P56: 3.6888795 | Q56: 4.5228749 | R56: 4.7933081 | S56: 0.031 | T56: 3.1267605 | U56: 3.1738785 | V56: 0.030529205 | W56: 0.039220713 | X56: -19 | Y56: 28.6 | Z56: 1.1 | AA56: 0.009 | AB56: 0.69314718 | AC56: 3.3877744 | AD56: 2.9957323 | AE56: 0.74193734 | AF56: 0.0089597414 | AG56: =AND("Zeta" ='Keto-CTA with change &Ln-Values'!$B67) -> FALSE | AH56: =ABS(X56) > 0 -> TRUE
A57: 77 | B57: Zeta | C57: 3 | D57: 3 | E57: 360 | F57: 353 | G57: 174.6 | H57: 210 | I57: 128.6 | J57: 140.7 | K57: 0.113 | L57: 0.121 | M57: 1.3862944 | N57: 1.3862944 | O57: 5.888878 | P57: 5.8692969 | Q57: 5.1682087 | R57: 5.3518581 | S57: 0.113 | T57: 4.8644528 | U57: 4.9537121 | V57: 0.10705907 | W57: 0.11422114 | X57: -7 | Y57: 35.4 | Z57: 12.1 | AA57: 0.008 | AB57: 0 | AC57: 3.5945688 | AD57: 2.0794415 | AE57: 2.5726122 | AF57: 0.0079681696 | AG57: =AND("Zeta" ='Keto-CTA with change &Ln-Values'!$B78) -> FALSE | AH57: =ABS(X57) > 0 -> TRUE
...

Sheet Sheet1
A1: - | B1: - | C1: Cac1 vs. Cac0 -- Beta | M1: - | N1: - | O1: LnCac1 vs. LnCac0 -- Beta | AA1: - | AB1: - | AC1: Ln(Qangio0/Tcpv1) vs. Ln(Ncpv1/Tcpv1) -- Qangio | AL1: - | AM1: - | AN1: Ln(Ncpv0/Tcpv1) vs. Ln(Ncpv1/Tcpv1) -- Alpha | AX1: - | AY1: - | AZ1: Ln(Ncpv1/Tcpv1) vs. Ln(Ncpv0/Tcpv0) -- Alpha | BL1: - | BM1: - | BN1: Ln(Ncpv0/Tcpv1) vs. Ln(Ncpv1/Tcpv0) -- Alpha | BX1: - | BY1: - | BZ1: LnNcpv1 vs. LnNcpv0 -- Alpha | CJ1: - | CK1: - | CL1: growthCac vs LnDCac -- Eta
A2: - | B2: - | C2: Slope: 1.2122 N=40 R^2: 0.9742 p-value: 0.000001 y-int -0.5124 | M2: - | N2: - | O2: Slope: 0.8716 N=40 R^2: 0.9857 p-value: 0.000000 y-int 0.7957 | AA2: - | AB2: - | AC2: Slope: 0.8152 N=10 R^2: 0.9080 p-value: 0.022866 y-int -0.6147 | AL2: - | AM2: - | AN2: Slope: 0.8842 N=88 R^2: 0.9627 p-value: 0.000003 y-int -0.0921 | AX2: - | AY2: - | AZ2: Slope: 0.4428 N=88 R^2: 0.1083 p-value: 0.731243 y-int 1.6960 | BL2: - | BM2: - | BN2: Slope: 0.3223 N=88 R^2: 0.0932 p-value: 0.752096 y-int 1.4251 | BX2: - | BY2: - | BZ2: Slope: 0.8110 N=88 R^2: 0.9124 p-value: 0.001983 y-int 1.2190 | CJ2: - | CK2: - | CL2: Slope: -2.8201 N=17 R^2: 0.1597 p-value: 0.687961 y-int 14.3495
A3: Id | B3: Cac0 | C3: Cac1 | M3: Id | N3: LnCac0 | O3: LnCac1 | AA3: Id | AB3: Ln(Ncpv1/Tcpv1) | AC3: Ln(Qangio0/Tcpv1) | AL3: Id | AM3: Ln(Ncpv1/Tcpv1) | AN3: Ln(Ncpv0/Tcpv1) | AX3: Id | AY3: Ln(Ncpv0/Tcpv0) | AZ3: Ln(Ncpv1/Tcpv1) | BL3: Id | BM3: Ln(Ncpv1/Tcpv0) | BN3: Ln(Ncpv0/Tcpv1) | BX3: Id | BY3: LnNcpv0 | BZ3: LnNcpv1 | CJ3: Id | CK3: LnDCac | CL3: growthCac
A4: 17 | B4: 0 | C4: 1 | M4: 17 | N4: 0 | O4: 0.69314718 | AA4: 2 | AB4: 0 | AC4: 0 | AL4: 1 | AM4: 0 | AN4: 0 | AX4: 1 | AY4: 0 | AZ4: 0 | BL4: 1 | BM4: 0 | BN4: 0 | BX4: 1 | BY4: 2.3321439 | BZ4: 2.9856819 | CJ4: 84 | CK4: 2.944439 | CL4: 0.95985855
A5: 49 | B5: 0 | C5: 2 | M5: 49 | N5: 0 | O5: 1.0986123 | AA5: 53 | AB5: 2.4882124 | AC5: 0.3345783 | AL5: 9 | AM5: 0 | AN5: 0 | AX5: 3 | AY5: 0 | AZ5: 4.7621739 | BL5: 9 | BM5: 0 | BN5: 0 | BX5: 3 | BY5: 2.014903 | BZ5: 3.1863526 | CJ5: 79 | CK5: 3.9318256 | CL5: 1.0432097
A6: 50 | B6: 0 | C6: 1 | M6: 50 | N6: 0 | O6: 0.69314718 | AA6: 86 | AB6: 1.5203469 | AC6: 0.40574308 | AL6: 10 | AM6: 0 | AN6: 0 | AX6: 4 | AY6: 0 | AZ6: 2.4079456 | BL6: 10 | BM6: 0 | BN6: 0 | BX6: 4 | BY6: 1.0296194 | BZ6: 2.3125354 | CJ6: 76 | CK6: 3.6109179 | CL6: 1.6509249
A7: 52 | B7: 0 | C7: 1 | M7: 52 | N7: 0 | O7: 0.69314718 | AA7: 96 | AB7: 1.0327317 | AC7: 0.4186859 | AL7: 12 | AM7: 0 | AN7: 0 | AX7: 5 | AY7: 0 | AZ7: 3.7455748 | BL7: 12 | BM7: 0 | BN7: 0 | BX7: 5 | BY7: 2.8094027 | BZ7: 3.2503745 | CJ7: 62 | CK7: 2.7080502 | CL7: 1.659298
A8: 53 | B8: 0 | C8: 1 | M8: 53 | N8: 0 | O8: 0.69314718 | AA8: 93 | AB8: 1.5514594 | AC8: 0.50531488 | AL8: 13 | AM8: 0 | AN8: 0 | AX8: 6 | AY8: 0 | AZ8: 3.2027464 | BL8: 13 | BM8: 0 | BN8: 0 | BX8: 6 | BY8: 2.4336134 | BZ8: 2.5494452 | CJ8: 80 | CK8: 3.4657359 | CL8: 1.8001193
A9: 57 | B9: 4 | C9: 6 | M9: 57 | N9: 1.6094379 | O9: 1.9459101 | AA9: 87 | AB9: 1.6454409 | AC9: 0.63215996 | AL9: 16 | AM9: 0 | AN9: 0 | AX9: 8 | AY9: 0 | AZ9: 6.7165948 | BL9: 16 | BM9: 0 | BN9: 0 | BX9: 7 | BY9: 3.8999504 | BZ9: 4.3993753 | CJ9: 99 | CK9: 4.3694479 | CL9: 2.0510717
A10: 59 | B10: 37 | C10: 37 | M10: 59 | N10: 3.6375862 | O10: 3.6375862 | AA10: 100 | AB10: 2.0252613 | AC10: 0.78529718 | AL10: 18 | AM10: 0 | AN10: 0 | AX10: 9 | AY10: 0 | AZ10: 0 | BL10: 18 | BM10: 0 | BN10: 0 | BX10: 8 | BY10: 4.1987046 | BZ10: 4.4248466 | CJ10: 96 | CK10: 5.3612922 | CL10: 2.1458241
A11: 61 | B11: 9 | C11: 13 | M11: 61 | N11: 2.3025851 | O11: 2.6390573 | AA11: 85 | AB11: 1.6758709 | AC11: 1.0238818 | AL11: 20 | AM11: 0 | AN11: 0 | AX11: 10 | AY11: 0 | AZ11: 0 | BL11: 19 | BM11: 0 | BN11: 0 | BX11: 9 | BY11: 1.5686159 | BZ11: 2.6461748 | CJ11: 98 | CK11: 4.060443 | CL11: 3.5578537
A12: 62 | B12: 27 | C12: 41 | M12: 62 | N12: 3.3322045 | O12: 3.7376696 | AA12: 82 | AB12: 1.6460477 | AC12: 1.0438723 | AL12: 21 | AM12: 0 | AN12: 0 | AX12: 12 | AY12: 0 | AZ12: 0 | BL12: 20 | BM12: 0 | BN12: 0 | BX12: 10 | BY12: 3.7796338 | BZ12: 4.1805223 | CJ12: 86 | CK12: 3.7841896 | CL12: 3.7371233
A13: 64 | B13: 63 | C13: 67 | M13: 64 | N13: 4.1588831 | O13: 4.2195077 | AA13: 48 | AB13: 6.9479371 | AC13: 5.4424177 | AL13: 24 | AM13: 0 | AN13: 0 | AX13: 13 | AY13: 0 | AZ13: 0 | BL13: 21 | BM13: 0 | BN13: 0 | BX13: 11 | BY13: 3.1223649 | BZ13: 3.8155121 | CJ13: 78 | CK13: 2.8332133 | CL13: 3.8452245
A14: 67 | B14: 4 | C14: 8 | M14: 67 | N14: 1.6094379 | O14: 2.1972246 | AA14: Regression Set Lower Upper Slope Std Err xSD ySD p-value | AL14: 25 | AM14: 0 | AN14: 0 | AX14: 14 | AY14: 0 | AZ14: 6.3279368 | BL14: 24 | BM14: 0 | BN14: 0 | BX14: 12 | BY14: 1.7749524 | BZ14: 2.8735646 | CJ14: 100 | CK14: 3.5835189 | CL14: 4.7148141
A15: 68 | B15: 0 | C15: 3 | M15: 68 | N15: 0 | O15: 1.3862944 | AA15: Ln(Qangio0/Tcpv1) vs. Ln(Ncpv1/Tcpv1) Qangio 0.1461 1.4844 0.8152 0.2902 0.613 0.524 0.02286629 | AL15: 26 | AM15: 0 | AN15: 0 | AX15: 16 | AY15: 0 | AZ15: 0 | BL15: 25 | BM15: 0 | BN15: 0 | BX15: 13 | BY15: 3.3603754 | BZ15: 3.6963515 | CJ15: 93 | CK15: 3.4657359 | CL15: 4.7877717
A16: 69 | B16: 21 | C16: 21 | M16: 69 | N16: 3.0910425 | O16: 3.0910425 | AL16: 29 | AM16: 0 | AN16: 0 | AX16: 18 | AY16: 0 | AZ16: 0 | BL16: 26 | BM16: 0 | BN16: 0 | BX16: 14 | BY16: 3.152736 | BZ16: 4.0412953 | CJ16: 82 | CK16: 3.3322045 | CL16: 5.2423129
A17: 70 | B17: 10 | C17: 18 | M17: 70 | N17: 2.3978953 | O17: 2.944439 | AL17: 32 | AM17: 0 | AN17: 0 | AX17: 19 | AY17: 0 | AZ17: 1.8625285 | BL17: 29 | BM17: 0 | BN17: 0 | BX17: 15 | BY17: 3.314186 | BZ17: 4.2752763 | CJ17: 85 | CK17: 3.4657359 | CL17: 5.3028537
A18: 71 | B18: 3 | C18: 5 | M18: 71 | N18: 1.3862944 | O18: 1.7917595 | AL18: 33 | AM18: 0 | AN18: 0 | AX18: 20 | AY18: 0 | AZ18: 0 | BL18: 32 | BM18: 0 | BN18: 0 | BX18: 16 | BY18: 0 | BZ18: 0 | CJ18: 88 | CK18: 2.5649494 | CL18: 5.422271
A19: 72 | B19: 12 | C19: 17 | M19: 72 | N19: 2.5649494 | O19: 2.8903718 | AL19: 35 | AM19: 0 | AN19: 0 | AX19: 21 | AY19: 0 | AZ19: 0 | BL19: 33 | BM19: 0 | BN19: 0 | BX19: 17 | BY19: 1.9878743 | BZ19: 3.034953 | CJ19: 83 | CK19: 3.3672958 | CL19: 5.7114559
A20: 73 | B20: 39 | C20: 49 | M20: 73 | N20: 3.6888795 | O20: 3.912023 | AL20: 36 | AM20: 0 | AN20: 0 | AX20: 22 | AY20: 0 | AZ20: 3.5553481 | BL20: 35 | BM20: 0 | BN20: 0 | BX20: 18 | BY20: 2.1972246 | BZ20: 2.7911651 | CJ20: 90 | CK20: 2.5649494 | CL20: 22.756573
A21: 74 | B21: 2 | C21: 7 | M21: 74 | N21: 1.0986123 | O21: 2.0794415 | AL21: 39 | AM21: 0 | AN21: 0 | AX21: 24 | AY21: 0 | AZ21: 0 | BL21: 36 | BM21: 0 | BN21: 0 | BX21: 19 | BY21: 0 | BZ21: 2.6810215 | CJ21: Regression Set Mean X moe X Mean Y moe Y Slope xSD p-value
A22: 75 | B22: 21 | C22: 31 | M22: 75 | N22: 3.0910425 | O22: 3.4657359 | AL22: 41 | AM22: 0 | AN22: 0 | AX22: 25 | AY22: 0 | AZ22: 0 | BL22: 39 | BM22: 0 | BN22: 0 | BX22: 20 | BY22: 3.8437442 | BZ22: 4.1743873 | CJ22: growthCac vs LnDCac Gamma 0.000 0.000 0.000 0.000 NaN 0.000 1.00000000
A23: 76 | B23: 69 | C23: 105 | M23: 76 | N23: 4.2484952 | O23: 4.6634391 | AL23: 42 | AM23: 0 | AN23: 0 | AX23: 26 | AY23: 0 | AZ23: 0 | BL23: 41 | BM23: 0 | BN23: 0 | BX23: 21 | BY23: 2.6741486 | BZ23: 3.0773123 | CJ23: growthCac vs LnDCac Theta 1.318 0.064 7.825 1.406 -0.0393 0.147 0.99866018
A24: 78 | B24: 81 | C24: 97 | M24: 78 | N24: 4.4067192 | O24: 4.5849675 | AL24: 44 | AM24: 0 | AN24: 0 | AX24: 28 | AY24: 0 | AZ24: 3.988984 | BL24: 42 | BM24: 0 | BN24: 0 | BX24: 22 | BY24: 0.99325177 | BZ24: 2.0541237 | CJ24: growthCac vs LnDCac BetaUZeta 2.068 0.052 5.994 0.449 -0.3717 0.188 0.96628381
A25: 79 | B25: 53 | C25: 103 | M25: 79 | N25: 3.988984 | O25: 4.6443909 | AL25: 46 | AM25: 0 | AN25: 0 | AX25: 29 | AY25: 0 | AZ25: 0 | BL25: 44 | BM25: 0 | BN25: 0 | BX25: 23 | BY25: 3.0910425 | BZ25: 4.2239098 | CJ25: growthCac vs LnDCac Qangio 2.478 0.445 6.128 2.505 -0.5772 0.622 0.92887175
A26: 80 | B26: 66 | C26: 97 | M26: 80 | N26: 4.2046926 | O26: 4.5849675 | AL26: 60 | AM26: 0 | AN26: 0 | AX26: 30 | AY26: 0 | AZ26: 5.288267 | BL26: 46 | BM26: 0 | BN26: 0 | BX26: 24 | BY26: 1.9021075 | BZ26: 2.3887628 | CJ26: growthCac vs LnDCac Beta 2.243 0.066 6.409 0.615 -1.4488 0.206 0.87888498
A27: 81 | B27: 80 | C27: 81 | M27: 81 | N27: 4.3944492 | O27: 4.4067192 | AL27: 99 | AM27: 0.64562591 | AN27: 0.48779538 | AX27: 31 | AY27: 0 | AZ27: 4.5108595 | BL27: 60 | BM27: 0 | BN27: 0 | BX27: 25 | BY27: 2.8622009 | BZ27: 4.0842942 | CJ27: growthCac vs LnDCac Alpha 1.020 0.032 2.913 0.197 1.2592 0.152 0.83562200
A28: 82 | B28: 191 | C28: 218 | M28: 82 | N28: 5.2574954 | O28: 5.3890717 | AL28: 90 | AM28: 0.74161482 | AN28: 0.60469828 | AX28: 32 | AY28: 0 | AZ28: 0 | BL28: 99 | BM28: 0.78740584 | BN28: 0.48779538 | BX28: 26 | BY28: 0 | BZ28: 2.3223877 | CJ28: growthCac vs LnDCac Omega 1.075 0.028 3.117 0.175 1.3866 0.142 0.82118825
A29: 83 | B29: 217 | C29: 245 | M29: 83 | N29: 5.3844951 | O29: 5.5053315 | AL29: 96 | AM29: 1.0327317 | AN29: 0.78278587 | AX29: 33 | AY29: 0 | AZ29: 0 | BL29: 90 | BM29: 0.8567963 | BN29: 0.60469828 | BX29: 27 | BY29: 3.1904764 | BZ29: 3.2846636 | CJ29: growthCac vs LnDCac Zeta 1.485 0.269 4.611 1.928 2.1745 0.423 0.77728038
A30: 84 | B30: 17 | C30: 35 | M30: 84 | N30: 2.8903718 | O30: 3.5835189 | AL30: 83 | AM30: 1.1202954 | AN30: 1.070247 | AX30: 34 | AY30: 0 | AZ30: 3.5457786 | BL30: 96 | BM30: 1.0516369 | BN30: 0.78278587 | BX30: 28 | BY30: 1.8405496 | BZ30: 1.8405496 | CJ30: growthCac vs LnDCac Eta 3.495 0.091 4.493 0.641 -2.8201 0.177 0.68796130
A31: 85 | B31: 222 | C31: 253 | M31: 85 | N31: 5.4071718 | O31: 5.5373343 | AL31: 98 | AM31: 1.2789421 | AN31: 1.0605094 | AX31: 35 | AY31: 0 | AZ31: 0 | BL31: 76 | BM31: 1.4769387 | BN31: 0.80602001 | BX31: 29 | BY31: 4.6259527 | BZ31: 5.0600602
A32: 86 | B32: 211 | C32: 254 | M32: 86 | N32: 5.3565863 | O32: 5.5412635 | AL32: 76 | AM32: 1.2818357 | AN32: 0.80602001 | AX32: 36 | AY32: 0 | AZ32: 0 | BL32: 64 | BM32: 1.5070558 | BN32: 0.93059713 | BX32: 30 | BY32: 2.3887628 | BZ32: 3.6988298
A33: 87 | B33: 101 | C33: 103 | M33: 87 | N33: 4.6249728 | O33: 4.6443909 | AL33: 97 | AM33: 1.3492289 | AN33: 1.0331601 | AX33: 39 | AY33: 0 | AZ33: 0 | BL33: 97 | BM33: 1.8664918 | BN33: 1.0331601 | BX33: 31 | BY33: 1.458615 | BZ33: 2.3025851
A34: 88 | B34: 88 | C34: 100 | M34: 88 | N34: 4.4886364 | O34: 4.6151205 | AL34: 92 | AM34: 1.3687257 | AN34: 1.1977205 | AX34: 40 | AY34: 0 | AZ34: 5.5412635 | BL34: 17 | BM34: 3.034953 | BN34: 1.0483505 | BX34: 32 | BY34: 0 | BZ34: 1.5892352
A35: 90 | B35: 388 | C35: 400 | M35: 90 | N35: 5.9635793 | O35: 5.9939614 | AL35: 64 | AM35: 1.3906078 | AN35: 0.93059713 | AX35: 41 | AY35: 0 | AZ35: 0 | BL35: 98 | BM35: 1.399525 | BN35: 1.0605094 | BX35: 33 | BY35: 2.7972813 | BZ35: 3.2846636
A36: 91 | B36: 119 | C36: 124 | M36: 91 | N36: 4.7874917 | O36: 4.8283137 | AL36: 80 | AM36: 1.4296663 | AN36: 1.3260021 | AX36: 42 | AY36: 0 | AZ36: 0 | BL36: 83 | BM36: 1.2438187 | BN36: 1.070247 | BX36: 34 | BY36: 3.2188758 | BZ36: 3.7232809
A37: 92 | B37: 295 | C37: 300 | M37: 92 | N37: 5.6903595 | O37: 5.7071103 | AL37: 62 | AM37: 1.4804077 | AN37: 1.3813479 | AX37: 44 | AY37: 0 | AZ37: 0 | BL37: 4 | BM37: 0 | BN37: 1.0986123 | BX37: 35 | BY37: 3.3775875 | BZ37: 4.0775374
A38: 93 | B38: 199 | C38: 230 | M38: 93 | N38: 5.2983174 | O38: 5.4424177 | AL38: 86 | AM38: 1.5203469 | AN38: 1.3985212 | AX38: 46 | AY38: 0 | AZ38: 0 | BL38: 37 | BM38: 3.0155349 | BN38: 1.1631508 | BX38: 36 | BY38: 3.0773123 | BZ38: 3.2995337
A39: 96 | B39: 556 | C39: 768 | M39: 96 | N39: 6.3225652 | O39: 6.645091 | AL39: 93 | AM39: 1.5514594 | AN39: 1.349054 | AX39: 47 | AY39: 0 | AZ39: 6.8916259 | BL39: 92 | BM39: 1.4466798 | BN39: 1.1977205 | BX39: 37 | BY39: 1.1631508 | BZ39: 2.3702437
A40: 97 | B40: 47 | C40: 54 | M40: 97 | N40: 3.871201 | O40: 4.0073332 | AL40: 79 | AM40: 1.6248089 | AN40: 1.3794372 | AX40: 48 | AY40: 0 | AZ40: 6.9479371 | BL40: 87 | BM40: 1.6702314 | BN40: 1.2035087 | BX40: 38 | BY40: 2.5952547 | BZ40: 3.1780538
...

Sheet Sheet3
A1: > keto | B1: growth | C1: zeta | M1: > keto | N1: growth | O1: beta | Z1: - | AA1: - | AB1: GrowthCac vs. GrowthNcpv -- Eta
A2: Id | B2: Set | C2: Cac0 | D2: Cac1 | E2: DCac | F2: Cac-dbl-yrs | G2: Ncpv0 | H2: Ncpv1 | I2: DNcpv | J2: Ncpv-dbl-yrs | K2: QAngio-dbl-yrs | M2: Id | N2: Set | O2: Cac0 | P2: Cac1 | Q2: DCac | R2: Cac-dbl-yrs | S2: Ncpv0 | T2: Ncpv1 | U2: DNcpv | V2: Ncpv-dbl-yrs | Z2: - | AA2: - | AB2: Slope: 0.0059 N=17 R^2: 0.0000 p-value: 0.998225 y-int 4.4761
A3: 55 | B3: Zeta | C3: 0 | D3: 0 | E3: 0 | F3: Inf | G3: 68.2 | H3: 71.4 | I3: 3.2 | J3: 15.11662 | K3: NaN | M3: 72 | N3: Theta | O3: 12 | P3: 17 | Q3: 5 | R3: 1.99005 | S3: 290.2 | T3: 301 | U3: 10.8 | V3: 18.96958 | Z3: Id | AA3: GrowthNcpv | AB3: GrowthCac
A4: 54 | B4: Zeta | C4: 2 | D4: 0 | E4: -2 | F4: 0 | G4: 64.9 | H4: 68.5 | I4: 3.6 | J4: 12.83936 | K4: NaN | M4: 83 | N4: Eta | O4: 217 | P4: 245 | Q4: 28 | R4: 5.71146 | S4: 169 | T4: 182.2 | U4: 13.2 | V4: 9.21661 | Z4: 84 | AA4: 2.6644995 | AB4: 0.95985855
A5: 2 | B5: Zeta | C5: 0 | D5: 0 | E5: 0 | F5: Inf | G5: 193.3 | H5: 212.2 | I5: 18.9 | J5: 7.43036 | K5: Inf | M5: 75 | N5: Theta | O5: 21 | P5: 31 | Q5: 10 | R5: 1.77974 | S5: 106.8 | T5: 116.5 | U5: 9.7 | V5: 7.97332 | Z5: 79 | AA5: 2.1934164 | AB5: 1.0432097
A6: 77 | B6: Zeta | C6: 360 | D6: 353 | E6: -7 | F6: -35.29986 | G6: 174.6 | H6: 210 | I6: 35.4 | J6: 3.75466 | K6: NaN | M6: 67 | N6: Theta | O6: 4 | P6: 8 | Q6: 4 | R6: 1 | S6: 139.4 | T6: 153.6 | U6: 14.2 | V6: 7.14553 | Z6: 76 | AA6: 0.93356645 | AB6: 1.6509249
A7: 63 | B7: Zeta | C7: 68 | D7: 62 | E7: -6 | F7: -7.50376 | G7: 77.3 | H7: 96.1 | I7: 18.8 | J7: 3.18402 | K7: NaN | M7: 62 | N7: Eta | O7: 27 | P7: 41 | Q7: 14 | R7: 1.6593 | S7: 45.3 | T7: 51.6 | U7: 6.3 | V7: 5.32311 | Z7: 62 | AA7: 5.3231125 | AB7: 1.659298
A8: 95 | B8: Zeta | C8: 175 | D8: 193 | E8: 18 | F8: 7.07985 | G8: 73.4 | H8: 92.7 | I8: 19.3 | J8: 2.96922 | K8: NaN | M8: 80 | N8: Eta | O8: 66 | P8: 97 | Q8: 31 | R8: 1.80012 | S8: 78 | T8: 89.6 | U8: 11.6 | V8: 4.99938 | Z8: 80 | AA8: 4.9993849 | AB8: 1.8001193
A9: 66 | B9: Zeta | C9: 58 | D9: 39 | E9: -19 | F9: -1.74648 | G9: 91.1 | H9: 119.7 | I9: 28.6 | J9: 2.53871 | K9: NaN | M9: 91 | N9: Theta | O9: 119 | P9: 124 | Q9: 5 | R9: 16.8411 | S9: 183.5 | T9: 213.8 | U9: 30.3 | V9: 4.53552 | Z9: 99 | AA9: 1.8904726 | AB9: 2.0510717
A10: 94 | B10: Zeta | C10: 291 | D10: 351 | E10: 60 | F10: 3.69752 | G10: 174.9 | H10: 245 | I10: 70.1 | J10: 2.05655 | K10: NaN | M10: 86 | N10: Eta | O10: 211 | P10: 254 | Q10: 43 | R10: 3.73712 | S10: 365.6 | T10: 428.5 | U10: 62.9 | V10: 4.36626 | Z10: 96 | AA10: 1.6475078 | AB10: 2.1458241
A11: 65 | B11: Zeta | C11: 1 | D11: 0 | E11: -1 | F11: 0 | G11: 113.6 | H11: 162 | I11: 48.4 | J11: 1.95301 | K11: NaN | M11: 73 | N11: Theta | O11: 39 | P11: 49 | Q11: 10 | R11: 3.03667 | S11: 83.3 | T11: 97.7 | U11: 14.4 | V11: 4.34703 | Z11: 98 | AA11: 2.18439 | AB11: 3.5578537
A12: 56 | B12: Zeta | C12: 0 | D12: 0 | E12: 0 | F12: Inf | G12: 15.5 | H12: 31 | I12: 15.5 | J12: 1 | K12: NaN | M12: 61 | N12: Theta | O12: 9 | P12: 13 | Q12: 4 | R12: 1.88496 | S12: 12.8 | T12: 15.2 | U12: 2.4 | V12: 4.03344 | Z12: 86 | AA12: 4.3662567 | AB12: 3.7371233
A13: 51 | B13: Zeta | C13: 6 | D13: 0 | E13: -6 | F13: 0 | G13: 19.6 | H13: 42 | I13: 22.4 | J13: 0.90947 | K13: NaN | M13: 70 | N13: Theta | O13: 10 | P13: 18 | Q13: 8 | R13: 1.17925 | S13: 52.1 | T13: 62.5 | U13: 10.4 | V13: 3.80847 | Z13: 78 | AA13: 0.96976666 | AB13: 3.8452245
A14: 89 | B14: Zeta | C14: 135 | D14: 135 | E14: 0 | F14: Inf | G14: 46.2 | H14: 41.7 | I14: -4.5 | J14: -6.76382 | K14: NaN | M14: 68 | N14: Theta | O14: 0 | P14: 3 | Q14: 3 | R14: 0 | S14: 171.5 | T14: 211.9 | U14: 40.4 | V14: 3.27681 | Z14: 100 | AA14: 2.3328494 | AB14: 4.7148141
M15: 92 | N15: Theta | O15: 295 | P15: 300 | Q15: 5 | R15: 41.24129 | S15: 252.3 | T15: 319.7 | U15: 67.4 | V15: 2.92758 | Z15: 93 | AA15: 2.6192418 | AB15: 4.7877717
A16: > keto | B16: growth | C16: qangio | M16: 88 | N16: Eta | O16: 88 | P16: 100 | Q16: 12 | R16: 5.42227 | S16: 238.5 | T16: 307.3 | U16: 68.8 | V16: 2.73479 | Z16: 82 | AA16: 1.770968 | AB16: 5.2423129
A17: Id | B17: Set | C17: Cac0 | D17: Cac1 | E17: DCac | F17: Cac-dbl-yrs | G17: Ncpv0 | H17: Ncpv1 | I17: DNcpv | J17: Ncpv-dbl-yrs | K17: QAngio-dbl-yrs | M17: 84 | N17: Eta | O17: 17 | P17: 35 | Q17: 18 | R17: 0.95986 | S17: 58.9 | T17: 76.4 | U17: 17.5 | V17: 2.6645 | Z17: 85 | AA17: 1.8269386 | AB17: 5.3028537
A18: 2 | B18: Zeta | C18: 0 | D18: 0 | E18: 0 | F18: Inf | G18: 193.3 | H18: 212.2 | I18: 18.9 | J18: 7.43036 | K18: Inf | M18: 93 | N18: Eta | O18: 199 | P18: 230 | Q18: 31 | R18: 4.78777 | S18: 290.8 | T18: 378.9 | U18: 88.1 | V18: 2.61924 | Z18: 88 | AA18: 2.7347922 | AB18: 5.422271
A19: 86 | B19: Eta | C19: 211 | D19: 254 | E19: 43 | F19: 3.73712 | G19: 365.6 | H19: 428.5 | I19: 62.9 | J19: 4.36626 | K19: 1.35692 | M19: 90 | N19: Eta | O19: 388 | P19: 400 | Q19: 12 | R19: 22.75657 | S19: 147.2 | T19: 194.8 | U19: 47.6 | V19: 2.47392 | Z19: 83 | AA19: 9.2166143 | AB19: 5.7114559
A20: 93 | B20: Eta | C20: 199 | D20: 230 | E20: 31 | F20: 4.78777 | G20: 290.8 | H20: 378.9 | I20: 88.1 | J20: 2.61924 | K20: 2.91289 | M20: 71 | N20: Theta | O20: 3 | P20: 5 | Q20: 2 | R20: 1.35692 | S20: 164.2 | T20: 220 | U20: 55.8 | V20: 2.36939 | Z20: 90 | AA20: 2.4739248 | AB20: 22.756573
A21: 100 | B21: Eta | C21: 221 | D21: 256 | E21: 35 | F21: 4.71481 | G21: 450.6 | H21: 606.5 | I21: 155.9 | J21: 2.33285 | K21: 25.76042 | M21: 100 | N21: Eta | O21: 221 | P21: 256 | Q21: 35 | R21: 4.71481 | S21: 450.6 | T21: 606.5 | U21: 155.9 | V21: 2.33285 | Z21: Regression Set Mean X moe X Mean Y moe Y Slope xSD p-value
A22: 85 | B22: Eta | C22: 222 | D22: 253 | E22: 31 | F22: 5.30285 | G22: 244.9 | H22: 357.9 | I22: 113 | J22: 1.82694 | K22: 0.92898 | M22: 74 | N22: Theta | O22: 2 | P22: 7 | Q22: 5 | R22: 0.55329 | S22: 141.1 | T22: 191 | U22: 49.9 | V22: 2.28909 | Z22: GrowthCac vs. GrowthNcpv Gamma 1.585 0.094 0.000 0.000 0.0000 0.324 1.00000000
A23: 82 | B23: Eta | C23: 191 | D23: 218 | E23: 27 | F23: 5.24231 | G23: 233.8 | H23: 345.8 | I23: 112 | J23: 1.77097 | K23: 1.99894 | M23: 79 | N23: Eta | O23: 53 | P23: 103 | Q23: 50 | R23: 1.04321 | S23: 130.5 | T23: 179 | U23: 48.5 | V23: 2.19342 | Z23: GrowthCac vs. GrowthNcpv Zeta 3.916 1.095 -2.814 2.062 0.0000 1.724 0.99999573
A24: 96 | B24: Eta | C24: 556 | D24: 768 | E24: 212 | F24: 2.14582 | G24: 255.8 | H24: 389.6 | I24: 133.8 | J24: 1.64751 | K24: 0.90454 | M24: 98 | N24: Eta | O24: 265 | P24: 322 | Q24: 57 | R24: 3.55785 | S24: 200.3 | T24: 275.1 | U24: 74.8 | V24: 2.18439 | Z24: GrowthCac vs. GrowthNcpv Eta 2.950 0.262 4.493 0.641 0.0059 0.510 0.99822451
A25: 87 | B25: Theta | C25: 101 | D25: 103 | E25: 2 | F25: 35.34937 | G25: 100.5 | H25: 180.3 | I25: 79.8 | J25: 1.18595 | K25: 1.29126 | M25: 57 | N25: Theta | O25: 4 | P25: 6 | Q25: 2 | R25: 1.70951 | S25: 94.7 | T25: 130.8 | U25: 36.1 | V25: 2.14626 | Z25: GrowthCac vs. GrowthNcpv Omega 2.502 0.066 2.226 0.181 -0.0181 0.332 0.99481490
A26: 53 | B26: Theta | C26: 0 | D26: 1 | E26: 1 | F26: 0 | G26: 67.1 | H26: 166.7 | I26: 99.6 | J26: 0.76169 | K26: 0.38103 | M26: 49 | N26: Theta | O26: 0 | P26: 2 | Q26: 2 | R26: 0 | S26: 39.7 | T26: 57 | U26: 17.3 | V26: 1.91636 | Z26: GrowthCac vs. GrowthNcpv Alpha 2.309 0.064 2.913 0.197 0.1116 0.303 0.97132454
A27: 48 | B27: Gamma | C27: 0 | D27: 0 | E27: 0 | F27: Inf | G27: 26.6 | H27: 104 | I27: 77.4 | J27: 0.50837 | K27: 1.77336 | M27: 99 | N27: Eta | O27: 194 | P27: 272 | Q27: 78 | R27: 2.05107 | S27: 71.8 | T27: 103.6 | U27: 31.8 | V27: 1.89047 | Z27: GrowthCac vs. GrowthNcpv BetaUZeta 3.349 0.152 4.281 0.479 -0.2692 0.545 0.93339092
M28: 85 | N28: Eta | O28: 222 | P28: 253 | Q28: 31 | R28: 5.30285 | S28: 244.9 | T28: 357.9 | U28: 113 | V28: 1.82694 | Z28: GrowthCac vs. GrowthNcpv Beta 3.178 0.166 6.409 0.615 -0.3562 0.518 0.92570227
M29: 82 | N29: Eta | O29: 191 | P29: 218 | Q29: 27 | R29: 5.24231 | S29: 233.8 | T29: 345.8 | U29: 112 | V29: 1.77097 | Z29: GrowthCac vs. GrowthNcpv Theta 3.347 0.362 7.825 1.406 -0.4669 0.837 0.90896060
M30: 81 | N30: Theta | O30: 80 | P30: 81 | Q30: 1 | R30: 55.79763 | S30: 163.9 | T30: 248.2 | U30: 84.3 | V30: 1.67032 | Z30: GrowthCac vs. GrowthNcpv Qangio 2.445 0.491 6.128 2.505 -1.1913 0.687 0.83515486
M31: 96 | N31: Eta | O31: 556 | P31: 768 | Q31: 212 | R31: 2.14582 | S31: 255.8 | T31: 389.6 | U31: 133.8 | V31: 1.64751
M32: 59 | N32: Theta | O32: 37 | P32: 37 | Q32: 0 | R32: Inf | S32: 42.4 | T32: 64.7 | U32: 22.3 | V32: 1.64015 | Z32: - | AA32: - | AB32: GrowthCac vs. GrowthNcpv -- Theta
M33: 97 | N33: Theta | O33: 47 | P33: 54 | Q33: 7 | R33: 4.99254 | S33: 105.7 | T33: 166.7 | U33: 61 | V33: 1.52142 | Z33: - | AA33: - | AB33: Slope: -0.4669 N=23 R^2: 0.0145 p-value: 0.908961 y-int 9.3879
M34: 87 | N34: Theta | O34: 101 | P34: 103 | Q34: 2 | R34: 35.34937 | S34: 100.5 | T34: 180.3 | U34: 79.8 | V34: 1.18595 | Z34: Id | AA34: GrowthNcpv | AB34: GrowthCac
M35: 69 | N35: Theta | O35: 21 | P35: 21 | Q35: 0 | R35: Inf | S35: 53.7 | T35: 99.3 | U35: 45.6 | V35: 1.12756 | Z35: 81 | AA35: 1.6703212 | AB35: 55.79763
M36: 64 | N36: Theta | O36: 63 | P36: 67 | Q36: 4 | R36: 11.26009 | S36: 53.3 | T36: 104.7 | U36: 51.4 | V36: 1.02664 | Z36: 92 | AA36: 2.9275844 | AB36: 41.241286
M37: 78 | N37: Eta | O37: 81 | P37: 97 | Q37: 16 | R37: 3.84522 | S37: 82.4 | T37: 168.4 | U37: 86 | V37: 0.96977 | Z37: 87 | AA37: 1.1859528 | AB37: 35.349374
M38: 76 | N38: Eta | O38: 69 | P38: 105 | Q38: 36 | R38: 1.65092 | S38: 53.4 | T38: 112.2 | U38: 58.8 | V38: 0.93357 | Z38: 91 | AA38: 4.535522 | AB38: 16.841099
M39: 52 | N39: Theta | O39: 0 | P39: 1 | Q39: 1 | R39: 0 | S39: 20.8 | T39: 45.7 | U39: 24.9 | V39: 0.88058 | Z39: 64 | AA39: 1.0266371 | AB39: 11.260086
M40: 50 | N40: Theta | O40: 0 | P40: 1 | Q40: 1 | R40: 0 | S40: 26.3 | T40: 60.7 | U40: 34.4 | V40: 0.82875 | Z40: 97 | AA40: 1.5214246 | AB40: 4.9925449
...

Sheet Sheet2
A1: > keto | B1: betau | C1: zeta gr | D1: owth | X1: > keto | Y1: OMEGA | Z1: growth | AO1: - | AP1: - | AQ1: GeoMeanNcpv vs. OrdAsc -- BetaUZeta | BA1: - | BB1: - | BC1: Ln(Ncpv1/Ncpv0) vs. OrdAsc -- Gamma | BM1: - | BN1: - | BO1: Ln(Ncpv1/Ncpv0) vs. OrdAsc -- Omega | BY1: - | BZ1: - | CA1: TdNcpv vs. RankA -- Omega | CK1: - | CL1: - | CM1: GrowthNcpv vs. RankAsc -- BetaUZeta | CW1: - | CX1: - | CY1: Ncpv1/Ncpv0 vs. TdNcpv -- Gamma | DI1: - | DJ1: - | DK1: Cac1/Cac0 vs. TdCac -- Eta | DU1: - | DV1: - | DW1: cac1/cac0 vs TdCac -- Theta | EG1: - | EH1: - | EI1: Ncpv1/Ncpv0 vs. TdNcpv -- Gamma | ES1: - | ET1: - | EU1: Ncpv1/Ncpv0 vs. TdNcpv -- Gamma | FE1: - | FF1: - | FG1: Ncpv1/Ncpv0 vs. TdNcpv -- Zeta | FN1: - | FO1: - | FP1: Cac1/Cac0 vs. TdCac -- Zeta | FY1: - | FZ1: - | GA1: Cac0/Cac1 vs. TdCac -- Zeta | GK1: Regression | GL1: Set | GM1: Mean X | GN1: moe X | GO1: Mean Y | GP1: moe Y | GQ1: Slope | GR1: xSD | GS1: p-value
A2: Id | B2: Set | C2: Cac0 | D2: Cac1 | E2: DCac | F2: Cac-dbl-yrs | G2: Ncpv0 | H2: Ncpv1 | I2: DNcpv | J2: Ncpv-dbl-yrs | K2: QAngio-dbl-yrs | X2: Id | Y2: Set | Z2: Cac0 | AA2: Cac1 | AB2: DCac | AC2: Cac-dbl-yrs | AD2: Ncpv0 | AE2: Ncpv1 | AF2: DNcpv | AG2: Ncpv-dbl-yrs | AH2: QAngio-dbl-yrs | AI2: regressors | AO2: - | AP2: - | AQ2: Slope: 6.5901 N=52 R^2: 0.8638 p-value: 0.016996 y-int -27.9410 | AR2: 4674 | BA2: - | BB2: - | BC2: Slope: 0.0281 N=48 R^2: 0.8579 p-value: 0.020256 y-int 0.3440 | BM2: - | BN2: - | BO2: Slope: 0.0099 N=100 R^2: 0.7957 p-value: 0.053582 y-int 0.4588 | BY2: - | BZ2: - | CA2: Slope: 0.0880 N=97 R^2: 0.5545 p-value: 0.272377 y-int -1.9983 | CK2: - | CL2: - | CM2: Slope: 0.2001 N=52 R^2: 0.6070 p-value: 0.228662 y-int -1.9529 | CW2: - | CX2: - | CY2: Slope: -0.1451 N=48 R^2: 0.0760 p-value: 0.780156 y-int 2.2680 | DI2: - | DJ2: - | DK2: Slope: -0.0312 N=17 R^2: 0.2870 p-value: 0.560066 y-int 1.4815 | DU2: - | DV2: - | DW2: Slope: NaN N=23 R^2: NaN p-value: NaN y-int NaN | EG2: - | EH2: - | EI2: Slope: -0.1963 N=45 R^2: 0.1693 p-value: 0.661164 y-int 2.5058 | ES2: - | ET2: - | EU2: Slope: -0.1963 N=45 R^2: 0.1693 p-value: 0.661164 y-int 2.5058 | FE2: - | FF2: - | FG2: Slope: -0.0178 N=12 R^2: 0.0743 p-value: 0.801219 y-int 1.4112 | FN2: - | FO2: - | FP2: Slope: -0.0109 N=12 R^2: 0.0494 p-value: 0.839386 y-int 0.4589 | FY2: - | FZ2: - | GA2: Slope: -0.0153 N=12 R^2: 0.0826 p-value: 0.789786 y-int 0.4852 | GK2: Cac1/Cac0 vs. TdCac | GL2: Eta-17 | GM2: 4.493 | GN2: 0.641 | GO2: 1.341 | GP2: 0.037 | GQ2: -0.0312 | GR2: 1.247 | GS2: 0.56006633
A3: 77 | B3: Zeta | C3: 360 | D3: 353 | E3: -7 | F3: -35.29986 | G3: 174.6 | H3: 210 | I3: 35.4 | J3: 3.75466 | K3: NaN | X3: 89 | Y3: Zeta | Z3: 135 | AA3: 135 | AB3: 0 | AC3: 0 | AD3: 46.2 | AE3: 41.7 | AF3: -4.5 | AG3: -6.76382 | AH3: NaN | AI3: =IF(Table15[[#This Row],[Set]]="Zeta", -2, -20) -> -2 | AO3: Id | AP3: OrdAsc | AQ3: GeoMeanNcpv | BA3: Id | BB3: OrdAsc | BC3: Ln(Ncpv1/Ncpv0) | BD3: ln^2 | BM3: Id | BN3: OrdAsc | BO3: Ln(Ncpv1/Ncpv0) | BY3: Id | BZ3: RankA | CA3: TdNcpv | CK3: Id | CL3: RankAsc | CM3: GrowthNcpv | CW3: Id | CX3: TdNcpv | CY3: Ncpv1/Ncpv0 | DI3: Id | DJ3: TdCac | DK3: Cac1/Cac0 | DT3: Column1 | DU3: Id | DV3: TdCac | DW3: cac1/cac0 | EG3: Id | EH3: TdNcpv | EI3: Ncpv1/Ncpv0 | ES3: Id | ET3: TdNcpv | EU3: Ncpv1/Ncpv0 | FE3: Id | FF3: TdNcpv | FG3: Ncpv1/Ncpv0 | FN3: Id | FO3: TdCac | FP3: Cac1/Cac0 | FY3: Id | FZ3: TdCac | GA3: Cac0/Cac1 | GK3: Cac1/Cac0 vs. TdCac | GL3: Theta-17 | GM3: 10.587 | GN3: 2.184 | GO3: 1.433 | GP3: 0.079 | GQ3: -0.0141 | GR3: 4.249 | GS3: 0.69681804
